<?xml version="1.0" ?>
<robot name="urr_bot" xmlns:xacro="http://www.ros.org/wiki/xacro">

<xacro:include filename="$(find urr_bot_description)/urdf/materials.xacro" />
<xacro:include filename="$(find urr_bot_description)/urdf/urr_bot.trans" />
<xacro:include filename="$(find urr_bot_description)/urdf/urr_bot.gazebo" />
<link name="base_link">
  <inertial>
    <origin xyz="0.0014622385857804554 0.0003790265360908496 0.035072892228656324" rpy="0 0 0"/>
    <mass value="0.655722312951929"/>
    <inertia ixx="0.000584" iyy="0.002255" izz="0.002722" ixy="-0.0" iyz="0.0" ixz="-3.3e-05"/>
  </inertial>
  <visual>
    <origin xyz="0 0 0" rpy="0 0 0"/>
    <geometry>
      <mesh filename="package://urr_bot_description/meshes/base_link.stl" scale="0.001 0.001 0.001"/>
    </geometry>
    <material name="silver"/>
  </visual>
  <collision>
    <origin xyz="0 0 0" rpy="0 0 0"/>
    <geometry>
      <mesh filename="package://urr_bot_description/meshes/base_link.stl" scale="0.001 0.001 0.001"/>
    </geometry>
  </collision>
</link>

<link name="lidar_1">
  <inertial>
    <origin xyz="-3.4149261791960317e-07 2.653609604535284e-08 0.004584263465868918" rpy="0 0 0"/>
    <mass value="0.015296318351217206"/>
    <inertia ixx="2e-06" iyy="2e-06" izz="3e-06" ixy="-0.0" iyz="-0.0" ixz="0.0"/>
  </inertial>
  <visual>
    <origin xyz="-0.066117 -0.000379 -0.06" rpy="0 0 0"/>
    <geometry>
      <mesh filename="package://urr_bot_description/meshes/lidar_1.stl" scale="0.001 0.001 0.001"/>
    </geometry>
    <material name="blue"/>
  </visual>
  <collision>
    <origin xyz="-0.066117 -0.000379 -0.06" rpy="0 0 0"/>
    <geometry>
      <mesh filename="package://urr_bot_description/meshes/lidar_1.stl" scale="0.001 0.001 0.001"/>
    </geometry>
  </collision>
</link>

<link name="camera_1">
  <inertial>
    <origin xyz="0.0013792199193853605 2.653621699200831e-08 -1.3877787807814457e-16" rpy="0 0 0"/>
    <mass value="0.0003431856271826569"/>
    <inertia ixx="0.0" iyy="0.0" izz="0.0" ixy="-0.0" iyz="0.0" ixz="-0.0"/>
  </inertial>
  <visual>
    <origin xyz="-0.101117 -0.000379 -0.035" rpy="0 0 0"/>
    <geometry>
      <mesh filename="package://urr_bot_description/meshes/camera_1.stl" scale="0.001 0.001 0.001"/>
    </geometry>
    <material name="black"/>
  </visual>
  <collision>
    <origin xyz="-0.101117 -0.000379 -0.035" rpy="0 0 0"/>
    <geometry>
      <mesh filename="package://urr_bot_description/meshes/camera_1.stl" scale="0.001 0.001 0.001"/>
    </geometry>
  </collision>
</link>

<link name="left_wheel_1">
  <inertial>
    <origin xyz="-0.045000341011720686 0.007000026536090602 -1.5265566588595902e-16" rpy="0 0 0"/>
    <mass value="0.03579059430602171"/>
    <inertia ixx="1.1e-05" iyy="2.2e-05" izz="1.1e-05" ixy="-0.0" iyz="-0.0" ixz="0.0"/>
  </inertial>
  <visual>
    <origin xyz="-0.091117 -0.050379 -0.035" rpy="0 0 0"/>
    <geometry>
      <mesh filename="package://urr_bot_description/meshes/left_wheel_1.stl" scale="0.001 0.001 0.001"/>
    </geometry>
    <material name="black"/>
  </visual>
  <collision>
    <origin xyz="-0.091117 -0.050379 -0.035" rpy="0 0 0"/>
    <geometry>
      <mesh filename="package://urr_bot_description/meshes/left_wheel_1.stl" scale="0.001 0.001 0.001"/>
    </geometry>
  </collision>
</link>

<link name="right_wheel_1">
  <inertial>
    <origin xyz="-0.045000341011721005 -0.006999973463909029 2.2898349882893854e-16" rpy="0 0 0"/>
    <mass value="0.03579059430602171"/>
    <inertia ixx="1.1e-05" iyy="2.2e-05" izz="1.1e-05" ixy="0.0" iyz="0.0" ixz="0.0"/>
  </inertial>
  <visual>
    <origin xyz="-0.091117 0.049621 -0.035" rpy="0 0 0"/>
    <geometry>
      <mesh filename="package://urr_bot_description/meshes/right_wheel_1.stl" scale="0.001 0.001 0.001"/>
    </geometry>
    <material name="black"/>
  </visual>
  <collision>
    <origin xyz="-0.091117 0.049621 -0.035" rpy="0 0 0"/>
    <geometry>
      <mesh filename="package://urr_bot_description/meshes/right_wheel_1.stl" scale="0.001 0.001 0.001"/>
    </geometry>
  </collision>
</link>

<joint name="lidar_joint" type="fixed">
  <origin xyz="0.066117 0.000379 0.06" rpy="0 0 0"/>
  <parent link="base_link"/>
  <child link="lidar_1"/>
</joint>

<joint name="cam_joint" type="fixed">
  <origin xyz="0.101117 0.000379 0.035" rpy="0 0 0"/>
  <parent link="base_link"/>
  <child link="camera_1"/>
</joint>

<joint name="left_motor" type="continuous">
  <origin xyz="0.091117 0.050379 0.035" rpy="0 0 0"/>
  <parent link="base_link"/>
  <child link="left_wheel_1"/>
  <axis xyz="0.0 1.0 -0.0"/>
</joint>

<joint name="right_motor" type="continuous">
  <origin xyz="0.091117 -0.049621 0.035" rpy="0 0 0"/>
  <parent link="base_link"/>
  <child link="right_wheel_1"/>
  <axis xyz="-0.0 -1.0 0.0"/>
</joint>

</robot>
